Workbook

Sheet Liste audit
A1: IDENTIFICATION-LOCALISATION-DONNEES DU SITE | J1: Installation PV | M1: BUREAU DE CONTÔLE DRE | O1: Mise en service | P1: MATERIELS | R1: CONTACT | V1: AUDIT | X1: INFO COMPLEMENTAIRES
A2: ID référent | B2: Nom des projets | C2: Puissance EXE | D2: SPV | E2: Latitude | F2: Longitude | G2: Adresse | H2: Dept | I2: Type de centrale | J2: Installateur | K2: Date réelle démarrage centrale PV | L2: Date réelle fin centrale PV | M2: Entreprise | N2: Date de reception réelle des DRE 155/162 | O2: Date MES | P2: SI | Q2: Panneaux | R2: Contact Chargé Exploitation | S2: Numéro Chargé d'exploitation | T2: Contact Gestion actif | U2: Numéro Gestion actif | V2: Audit en toiture | W2: Audit hors toiture | X2: Sous performance non identifié | Y2: Ratio PR réel VS PR théorique OCTOBRE | Z2: Raison probable | AA2: Date prévisionnelle d'audit | AB2: Date réelle d'audit | AC2: Présence auto controle | AD2: Présence PV réception lot PV | AE2: Présence CR visite chantier lot PV
A3: 31971 | B3: Antunez - SCI ANAUJA | C3: 269.45 | D3: F2 DAVAI ENRSPV8 | E3: 43.3654 | F3: 3.2529 | G3: 253 Bd Robert Koch, 34500 Béziers, France | H3: 34 | I3: Ombrière simple | J3: LE TRIANGLE | K3: 45588 | L3: 45688 | M3: SOCOTEC POWER SERVICES | N3: 45713 | O3: 45744 | P3: Triangle IAB | Q3: DMEGC-DM425M10T-B54HSW-HBW | R3: =_xlfn.XLOOKUP(Tableau2[[#This Row],[ID référent]],Feuil4!A:A,Feuil4!BD:BD) -> Parfait MEZEME ONA | S3: =IF(Tableau2[[#This Row],[Contact Chargé Exploitation]]="Parfait MEZEME ONA","06 63 06 94 73","06 74 09 71 44") -> 06 63 06 94 73 | T3: Jean-Paul THOROGOOD | U3: =IF(Tableau2[[#This Row],[Contact Gestion actif]]="Victor PONTAIS","06 69 21 76 42","06 74 94 09 90") -> 06 74 94 09 90 | W3: X | Y3: 1.0043709 | AC3: Non | AD3: Non | AE3: Non
A4: 89219 | B4: EARL CADOT | C4: 309.4 | D4: F3 DAVAI ENRSPV10 | E4: 46.24919 | F4: 3.88361 | G4: La Maisonneuve, 42310 Urbise, France | H4: 42 | I4: Bâtiment à construire - C | J4: 3C instal | K4: 45638 | L4: 45699 | M4: SOCOTEC POWER SERVICES | N4: 45699 | O4: 45748 | P4: JORIS RS-R | Q4: DMEGC-DM455M10RT-54HSW-HBW | R4: =_xlfn.XLOOKUP(Tableau2[[#This Row],[ID référent]],Feuil4!A:A,Feuil4!BD:BD) -> Yasser BADREZZAMANE | S4: =IF(Tableau2[[#This Row],[Contact Chargé Exploitation]]="Parfait MEZEME ONA","06 63 06 94 73","06 74 09 71 44") -> 06 74 09 71 44 | T4: Jean-Paul THOROGOOD | U4: =IF(Tableau2[[#This Row],[Contact Gestion actif]]="Victor PONTAIS","06 69 21 76 42","06 74 94 09 90") -> 06 74 94 09 90 | V4: X | W4: X | Y4: 0.99454308 | AC4: Oui | AD4: Oui | AE4: Non
A5: 83705 | B5: Azemar | C5: 319 | D5: F3 DAVAI ENRSPV13 | E5: 44.25786 | F5: 2.45787 | G5: 12160 Camboulazet, France | H5: 12 | I5: Bâtiment à construire - C | J5: 3C instal | K5: 45705 | L5: 45737 | M5: BUREAU VERITAS | N5: 45754 | O5: 45783 | P5: DOMESOLAR NPA 3.45 | Q5: DMEGC-DM455M10RT-B54HSW | R5: =_xlfn.XLOOKUP(Tableau2[[#This Row],[ID référent]],Feuil4!A:A,Feuil4!BD:BD) -> Parfait MEZEME ONA | S5: =IF(Tableau2[[#This Row],[Contact Chargé Exploitation]]="Parfait MEZEME ONA","06 63 06 94 73","06 74 09 71 44") -> 06 63 06 94 73 | T5: Jean-Paul THOROGOOD | U5: =IF(Tableau2[[#This Row],[Contact Gestion actif]]="Victor PONTAIS","06 69 21 76 42","06 74 94 09 90") -> 06 74 94 09 90 | W5: X | Y5: 0.97390725 | AC5: Oui | AD5: Oui | AE5: Non
A6: 17996 | B6: Mathieu Montet | C6: 256.055 | D6: F2 DAVAI ENRSPV12 | E6: 45.53534 | F6: 5.45229 | G6: 127 Route de la Tour, 38110 Montagnieu, France | H6: 38 | I6: Toiture existante / Rénovation | J6: PROSUNFRANCE | K6: 45404 | L6: 45506 | M6: SOCOTEC POWER SERVICES | N6: 45496 | O6: 45567 | P6: DOMESOLAR Hb²/NPA 3.45 | Q6: DMEGC-DM415M10-54HSW-V | R6: =_xlfn.XLOOKUP(Tableau2[[#This Row],[ID référent]],Feuil4!A:A,Feuil4!BD:BD) -> Yasser BADREZZAMANE | S6: =IF(Tableau2[[#This Row],[Contact Chargé Exploitation]]="Parfait MEZEME ONA","06 63 06 94 73","06 74 09 71 44") -> 06 74 09 71 44 | T6: Jean-Paul THOROGOOD | U6: =IF(Tableau2[[#This Row],[Contact Gestion actif]]="Victor PONTAIS","06 69 21 76 42","06 74 94 09 90") -> 06 74 94 09 90 | W6: X | Y6: 0.90032451 | AC6: Oui | AD6: Oui | AE6: Non
A7: 17966 | B7: Hangar Laurent ROUX | C7: 123.41 | D7: F2 DAVAI ENRSPV8 | E7: 44.92766 | F7: 2.99036 | G7: Cros et Vareine, 15260 Neuvéglise-sur-Truyère, France | H7: 15 | I7: Toiture existante / Rénovation | J7: OFT | K7: 45441 | L7: 45469 | M7: SOCOTEC POWER SERVICES | N7: 45531 | O7: 45587 | P7: DOMESOLAR Ital Solar | Q7: DMEGC-DM430M10T-54HSW-HBW | R7: =_xlfn.XLOOKUP(Tableau2[[#This Row],[ID référent]],Feuil4!A:A,Feuil4!BD:BD) -> Parfait MEZEME ONA | S7: =IF(Tableau2[[#This Row],[Contact Chargé Exploitation]]="Parfait MEZEME ONA","06 63 06 94 73","06 74 09 71 44") -> 06 63 06 94 73 | T7: Jean-Paul THOROGOOD | U7: =IF(Tableau2[[#This Row],[Contact Gestion actif]]="Victor PONTAIS","06 69 21 76 42","06 74 94 09 90") -> 06 74 94 09 90 | W7: X | Y7: 0.67177711 | Z7: Pb AGCP qui déclenche | AC7: Oui | AD7: Non | AE7: Non
A8: 70087 | B8: Hangar Bernard MAGE | C8: 300.82 | D8: F2 DAVAI ENRSPV8 | E8: 44.75755 | F8: 2.04496 | G8: Broussoles, 46210 Montet-et-Bouxal, France | H8: 46 | I8: Bâtiment à construire - A2 | J8: Acrom | K8: 45537 | L8: 45569 | M8: SOCOTEC POWER SERVICES | N8: 45586 | O8: 45609 | P8: DOMESOLAR NPA 3.45 | Q8: JKM445N-54HL4R-V | R8: =_xlfn.XLOOKUP(Tableau2[[#This Row],[ID référent]],Feuil4!A:A,Feuil4!BD:BD) -> Parfait MEZEME ONA | S8: =IF(Tableau2[[#This Row],[Contact Chargé Exploitation]]="Parfait MEZEME ONA","06 63 06 94 73","06 74 09 71 44") -> 06 63 06 94 73 | T8: Jean-Paul THOROGOOD | U8: =IF(Tableau2[[#This Row],[Contact Gestion actif]]="Victor PONTAIS","06 69 21 76 42","06 74 94 09 90") -> 06 74 94 09 90 | V8: X | W8: X | Y8: 1.0216865 | AC8: Oui | AD8: Oui | AE8: Non
A9: 30489 | B9: Hangar Pierre MOURGUES | C9: 222.5 | D9: F2 DAVAI ENRSPV9 | E9: 44.38426 | F9: 1.16738 | G9: Mondounet - Fargues, 46800 Porte-du-Quercy, France | H9: 46 | I9: Bâtiment à construire - C | J9: Acrom | K9: 45439 | L9: 45546 | M9: SOCOTEC POWER SERVICES | N9: 45560 | O9: 45611 | P9: DOMESOLAR NPA 3.45 | Q9: DMEGC-DM445M10RT-54HSW-HBW | R9: =_xlfn.XLOOKUP(Tableau2[[#This Row],[ID référent]],Feuil4!A:A,Feuil4!BD:BD) -> Parfait MEZEME ONA | S9: =IF(Tableau2[[#This Row],[Contact Chargé Exploitation]]="Parfait MEZEME ONA","06 63 06 94 73","06 74 09 71 44") -> 06 63 06 94 73 | T9: Victor PONTAIS | U9: =IF(Tableau2[[#This Row],[Contact Gestion actif]]="Victor PONTAIS","06 69 21 76 42","06 74 94 09 90") -> 06 69 21 76 42 | W9: X | Y9: 0.9285786 | AC9: Oui | AD9: Oui | AE9: Non
A10: 58962 | B10: Hangar Karl Biteau | C10: 324.22 | D10: F2 DAVAI ENRSPV8 | E10: 45.7447 | F10: -0.92605 | G10: 17250 Sainte-Gemme, France | H10: 17 | I10: Bâtiment à construire - C | J10: Eiffage | K10: 45404 | L10: 45422 | M10: SOCOTEC POWER SERVICES | N10: 45526 | O10: 45615 | P10: DOMESOLAR NPA 3.45 | Q10: DMEGC-DM430M10T-54HSW-HBW | R10: =_xlfn.XLOOKUP(Tableau2[[#This Row],[ID référent]],Feuil4!A:A,Feuil4!BD:BD) -> Parfait MEZEME ONA | S10: =IF(Tableau2[[#This Row],[Contact Chargé Exploitation]]="Parfait MEZEME ONA","06 63 06 94 73","06 74 09 71 44") -> 06 63 06 94 73 | T10: Jean-Paul THOROGOOD | U10: =IF(Tableau2[[#This Row],[Contact Gestion actif]]="Victor PONTAIS","06 69 21 76 42","06 74 94 09 90") -> 06 74 94 09 90 | V10: X | W10: X | Y10: 0.97688227 | AC10: Oui | AD10: Oui | AE10: Non
A11: 28173 | B11: Burgat Et Fils Tp | C11: 113.03 | D11: F2 DAVAI ENRSPV6 | E11: 43.04294 | F11: 2.23988 | G11: La Plaine 11300 Cournanel | H11: 11 | I11: Toiture existante / Rénovation | J11: SOLARTIS | K11: 45488 | L11: 45551 | M11: SOCOTEC POWER SERVICES | N11: 45569 | O11: 45616 | P11: DOMESOLAR Ital Solar | Q11: DMEGC-DM445M10RT-54HSW-HBW | R11: =_xlfn.XLOOKUP(Tableau2[[#This Row],[ID référent]],Feuil4!A:A,Feuil4!BD:BD) -> Parfait MEZEME ONA | S11: =IF(Tableau2[[#This Row],[Contact Chargé Exploitation]]="Parfait MEZEME ONA","06 63 06 94 73","06 74 09 71 44") -> 06 63 06 94 73 | T11: Jean-Paul THOROGOOD | U11: =IF(Tableau2[[#This Row],[Contact Gestion actif]]="Victor PONTAIS","06 69 21 76 42","06 74 94 09 90") -> 06 74 94 09 90 | W11: X | X11: X | Y11: 0.85352021 | AC11: Oui | AD11: Oui | AE11: Non
A12: 29246 | B12: HANGAR Angelina SIMMONET | C12: 173.55 | D12: F2 DAVAI ENRSPV6 | E12: 46.63388 | F12: 3.58233 | G12: L'Étang Fouché, 03230 Paray-le-Frésil, France | H12: 3 | I12: Bâtiment à construire - A1 | J12: LE TRIANGLE | K12: 45594 | L12: 45615 | M12: SOCOTEC POWER SERVICES | N12: 45628 | O12: 45667 | P12: Triangle ISB | Q12: DMEGC-DM455M10RT-54HSW-HBW | R12: =_xlfn.XLOOKUP(Tableau2[[#This Row],[ID référent]],Feuil4!A:A,Feuil4!BD:BD) -> Yasser BADREZZAMANE | S12: =IF(Tableau2[[#This Row],[Contact Chargé Exploitation]]="Parfait MEZEME ONA","06 63 06 94 73","06 74 09 71 44") -> 06 74 09 71 44 | T12: Jean-Paul THOROGOOD | U12: =IF(Tableau2[[#This Row],[Contact Gestion actif]]="Victor PONTAIS","06 69 21 76 42","06 74 94 09 90") -> 06 74 94 09 90 | W12: X | Y12: 0.9591879 | AC12: Oui | AD12: Oui | AE12: Non
A13: 76547 | B13: Maymat | C13: 345.8 | D13: F2 DAVAI ENRSPV9 | E13: 46.51456 | F13: 3.41436 | G13: Les Sorreaux, 03400 Toulon-sur-Allier, France | H13: 3 | I13: Bâtiment à construire - C | J13: LE TRIANGLE | K13: 45561 | L13: 45618 | M13: SOCOTEC POWER SERVICES | N13: 45624 | O13: 45672 | P13: Triangle ISB | Q13: DMEGC-DM455M10RT-54HSW-HBW | R13: =_xlfn.XLOOKUP(Tableau2[[#This Row],[ID référent]],Feuil4!A:A,Feuil4!BD:BD) -> Yasser BADREZZAMANE | S13: =IF(Tableau2[[#This Row],[Contact Chargé Exploitation]]="Parfait MEZEME ONA","06 63 06 94 73","06 74 09 71 44") -> 06 74 09 71 44 | T13: Victor PONTAIS | U13: =IF(Tableau2[[#This Row],[Contact Gestion actif]]="Victor PONTAIS","06 69 21 76 42","06 74 94 09 90") -> 06 69 21 76 42 | W13: X | X13: X | Y13: 0.84186718 | AC13: Oui | AD13: Oui | AE13: Non
A14: 22147 | B14: HANGAR Christian MIGNARD | C14: 97.11 | D14: F2 DAVAI ENRSPV9 | E14: 43.297058 | F14: 2.665955 | G14: Chemin de Rieux 11700 Pépieux | H14: 11 | I14: Bâtiment à construire - B | J14: Solartis | K14: 45579 | L14: 45623 | M14: SOCOTEC POWER SERVICES | N14: 45628 | O14: 45642 | P14: DOMESOLAR NPA 3.45 | Q14: DMEGC-DM415M10-54HSW-V | R14: =_xlfn.XLOOKUP(Tableau2[[#This Row],[ID référent]],Feuil4!A:A,Feuil4!BD:BD) -> Parfait MEZEME ONA | S14: =IF(Tableau2[[#This Row],[Contact Chargé Exploitation]]="Parfait MEZEME ONA","06 63 06 94 73","06 74 09 71 44") -> 06 63 06 94 73 | T14: Victor PONTAIS | U14: =IF(Tableau2[[#This Row],[Contact Gestion actif]]="Victor PONTAIS","06 69 21 76 42","06 74 94 09 90") -> 06 69 21 76 42 | V14: X | W14: X | Y14: 0.9985421 | AC14: Non | AD14: Non | AE14: Non
A15: 60830 | B15: DUMONT GUY | C15: 232.2 | D15: F2 DAVAI ENRSPV8 | E15: 46.628738 | F15: 3.585084 | G15: Les Sabots, 03230 Chevagnes, France | H15: 3 | I15: Bâtiment à construire - A1 | J15: LE TRIANGLE | K15: 45565 | L15: 45618 | M15: SOCOTEC POWER SERVICES | N15: 45623 | O15: 45687 | P15: Triangle ISB | Q15: DMEGC-DM430M10T-54HSW-HBW | R15: =_xlfn.XLOOKUP(Tableau2[[#This Row],[ID référent]],Feuil4!A:A,Feuil4!BD:BD) -> Yasser BADREZZAMANE | S15: =IF(Tableau2[[#This Row],[Contact Chargé Exploitation]]="Parfait MEZEME ONA","06 63 06 94 73","06 74 09 71 44") -> 06 74 09 71 44 | T15: Jean-Paul THOROGOOD | U15: =IF(Tableau2[[#This Row],[Contact Gestion actif]]="Victor PONTAIS","06 69 21 76 42","06 74 94 09 90") -> 06 74 94 09 90 | W15: X | Y15: 1.2162829 | AC15: Oui | AD15: Oui | AE15: Non
A16: 95686 | B16: MARTEL 184 Construction | C16: 499.95 | D16: F2 DAVAI ENRSPV9 | E16: 46.21212 | F16: 1.66779 | G16: Lieudit Les Ribières, 23240 Le Grand Bourg | H16: 23 | I16: Bâtiment à construire - A2 | J16: NEOXOM | K16: 45530 | L16: 45567 | M16: SOCOTEC POWER SERVICES | N16: 45601 | O16: 45692 | P16: DOMESOLAR NPA 3.45 | Q16: JKM450N-54HL4R-V | R16: =_xlfn.XLOOKUP(Tableau2[[#This Row],[ID référent]],Feuil4!A:A,Feuil4!BD:BD) -> Parfait MEZEME ONA | S16: =IF(Tableau2[[#This Row],[Contact Chargé Exploitation]]="Parfait MEZEME ONA","06 63 06 94 73","06 74 09 71 44") -> 06 63 06 94 73 | T16: Victor PONTAIS | U16: =IF(Tableau2[[#This Row],[Contact Gestion actif]]="Victor PONTAIS","06 69 21 76 42","06 74 94 09 90") -> 06 69 21 76 42 | W16: X | Y16: 0.68927501 | Z16: Modification des shelters jusqu'au 6 octobre | AC16: Non | AD16: Oui | AE16: Non
A17: 95689 | B17: BOUCHARDY 203 LOC | C17: 498.68 | D17: F2 DAVAI ENRSPV9 | E17: 46.18866 | F17: 1.70087 | G17: Saint-Martin, 23320 Saint-Vaury, France | H17: 23 | I17: Toiture existante / Rénovation | J17: OFT | K17: 45635 | L17: 45681 | M17: SOCOTEC POWER SERVICES | N17: 45691 | O17: 45728 | P17: DOMESOLAR NPA 3.45 | Q17: DMEGC-DM455M10RT-54HSW-HBW | R17: =_xlfn.XLOOKUP(Tableau2[[#This Row],[ID référent]],Feuil4!A:A,Feuil4!BD:BD) -> Parfait MEZEME ONA | S17: =IF(Tableau2[[#This Row],[Contact Chargé Exploitation]]="Parfait MEZEME ONA","06 63 06 94 73","06 74 09 71 44") -> 06 63 06 94 73 | T17: Victor PONTAIS | U17: =IF(Tableau2[[#This Row],[Contact Gestion actif]]="Victor PONTAIS","06 69 21 76 42","06 74 94 09 90") -> 06 69 21 76 42 | W17: X | X17: X | Y17: 0.8724129 | AC17: Oui | AD17: Oui | AE17: Non
A18: 95691 | B18: BOULOIR 206 LOC | C18: 499.14 | D18: F2 DAVAI ENRSPV9 | E18: 46.21057 | F18: 1.67252 | G18: 23240 Le Grand-Bourg, France | H18: 23 | I18: Toiture existante / Rénovation | J18: OFT | K18: 45642 | L18: 45688 | M18: SOCOTEC POWER SERVICES | N18: 45691 | O18: 45727 | P18: DOMESOLAR NPA 3.45 | Q18: DMEGC-DM455M10RT-54HSW-HBW | R18: =_xlfn.XLOOKUP(Tableau2[[#This Row],[ID référent]],Feuil4!A:A,Feuil4!BD:BD) -> Parfait MEZEME ONA | S18: =IF(Tableau2[[#This Row],[Contact Chargé Exploitation]]="Parfait MEZEME ONA","06 63 06 94 73","06 74 09 71 44") -> 06 63 06 94 73 | T18: Victor PONTAIS | U18: =IF(Tableau2[[#This Row],[Contact Gestion actif]]="Victor PONTAIS","06 69 21 76 42","06 74 94 09 90") -> 06 69 21 76 42 | W18: X | Y18: 0.9177162 | AC18: Oui | AD18: Oui | AE18: Non
A19: 83431 | B19: Hangar Renaud Sonnard | C19: 324.87 | D19: F3 DAVAI ENRSPV11 | E19: 46.41411 | F19: -0.53832 | G19: Les grandes versaines, 79160 Villiers-en-Plaine, France | H19: 79 | I19: Bâtiment à construire - A1 | J19: REGIESOLAIRE | K19: 45677 | L19: 45695 | M19: SOCOTEC POWER SERVICES | N19: 45707 | O19: 45736 | P19: DOMESOLAR NPA 3.45 | Q19: DMEGC-DM455M10RT-54HSW-HBW | R19: =_xlfn.XLOOKUP(Tableau2[[#This Row],[ID référent]],Feuil4!A:A,Feuil4!BD:BD) -> Yasser BADREZZAMANE | S19: =IF(Tableau2[[#This Row],[Contact Chargé Exploitation]]="Parfait MEZEME ONA","06 63 06 94 73","06 74 09 71 44") -> 06 74 09 71 44 | T19: Jean-Paul THOROGOOD | U19: =IF(Tableau2[[#This Row],[Contact Gestion actif]]="Victor PONTAIS","06 69 21 76 42","06 74 94 09 90") -> 06 74 94 09 90 | V19: X | W19: X | Y19: 1.1010636 | AC19: Non | AD19: Oui | AE19: Oui
A20: 96546 | B20: Hangar Fabrice COMBY | C20: 499.59 | D20: F3 DAVAI ENRSPV11 | E20: 45.452821 | F20: 1.2834 | G20: Besse, 19210 Saint-Éloy-les-Tuileries, France | H20: 19 | I20: Toiture existante / PV Ready | J20: HBBAT | K20: 45639 | L20: 45709 | M20: SOCOTEC POWER SERVICES | N20: 45722 | O20: 45741 | P20: DOMESOLAR NPA 3.45 | Q20: DMEGC-DM455M10RT-54HSW-HBW | R20: =_xlfn.XLOOKUP(Tableau2[[#This Row],[ID référent]],Feuil4!A:A,Feuil4!BD:BD) -> Parfait MEZEME ONA | S20: =IF(Tableau2[[#This Row],[Contact Chargé Exploitation]]="Parfait MEZEME ONA","06 63 06 94 73","06 74 09 71 44") -> 06 63 06 94 73 | T20: Jean-Paul THOROGOOD | U20: =IF(Tableau2[[#This Row],[Contact Gestion actif]]="Victor PONTAIS","06 69 21 76 42","06 74 94 09 90") -> 06 74 94 09 90 | V20: X | W20: X | X20: X | Y20: 0.8894752 | AC20: Oui | AD20: Oui | AE20: Non
A21: 82076 | B21: Hangar Julien Vaudin | C21: 348.88 | D21: F2 DAVAI ENRSPV7 | E21: 46.58741 | F21: 3.5494 | G21: Les Jacquets, 03230 Chevagnes, France | H21: 3 | I21: Toiture existante / Rénovation | J21: PROSUNFRANCE | K21: 45483 | L21: 45565 | M21: SOCOTEC POWER SERVICES | N21: 45574 | O21: 45751 | P21: DOMESOLAR NPA 3.45 | Q21: DMEGC-DM445M10RT-54HSW-HBW | R21: =_xlfn.XLOOKUP(Tableau2[[#This Row],[ID référent]],Feuil4!A:A,Feuil4!BD:BD) -> Yasser BADREZZAMANE | S21: =IF(Tableau2[[#This Row],[Contact Chargé Exploitation]]="Parfait MEZEME ONA","06 63 06 94 73","06 74 09 71 44") -> 06 74 09 71 44 | T21: Victor PONTAIS | U21: =IF(Tableau2[[#This Row],[Contact Gestion actif]]="Victor PONTAIS","06 69 21 76 42","06 74 94 09 90") -> 06 69 21 76 42 | W21: X | Y21: 0.97496649 | AC21: Oui | AD21: Oui | AE21: Non
A22: 98584 | B22: Hangar Richard VAN ZANTEN | C22: 330.785 | D22: F2 DAVAI ENRSPV7 | E22: 44.66239 | F22: 0.83643 | G22: La Tuque, 47210 Parranquet, France | H22: 47 | I22: Bâtiment à construire - A2 | J22: Acrom | K22: 45663 | L22: 45705 | M22: SOCOTEC POWER SERVICES | N22: 45729 | O22: 45763 | P22: DOMESOLAR NPA 3.45 | Q22: DMEGC-DM455M10RT-B54HSW | R22: =_xlfn.XLOOKUP(Tableau2[[#This Row],[ID référent]],Feuil4!A:A,Feuil4!BD:BD) -> Yasser BADREZZAMANE | S22: =IF(Tableau2[[#This Row],[Contact Chargé Exploitation]]="Parfait MEZEME ONA","06 63 06 94 73","06 74 09 71 44") -> 06 74 09 71 44 | T22: Victor PONTAIS | U22: =IF(Tableau2[[#This Row],[Contact Gestion actif]]="Victor PONTAIS","06 69 21 76 42","06 74 94 09 90") -> 06 69 21 76 42 | W22: X | Y22: 0.95449521 | AC22: Oui | AD22: Oui | AE22: Non
A23: 20614 | B23: HANGAR Benoit BERTELOOT | C23: 278.64 | D23: F2 DAVAI ENRSPV8 | E23: 48.107174 | F23: 3.120535 | G23: 127 Lieu Dit les Cleris 89150 Vernoy | H23: 89 | I23: Bâtiment à construire - A1 | J23: LE TRIANGLE | K23: 45376 | L23: 45660 | M23: SOCOTEC POWER SERVICES | N23: 45666 | O23: 45687 | P23: Triangle ISB | Q23: DMEGC-DM430M10T-54HSW-HBW | R23: =_xlfn.XLOOKUP(Tableau2[[#This Row],[ID référent]],Feuil4!A:A,Feuil4!BD:BD) -> Yasser BADREZZAMANE | S23: =IF(Tableau2[[#This Row],[Contact Chargé Exploitation]]="Parfait MEZEME ONA","06 63 06 94 73","06 74 09 71 44") -> 06 74 09 71 44 | T23: Jean-Paul THOROGOOD | U23: =IF(Tableau2[[#This Row],[Contact Gestion actif]]="Victor PONTAIS","06 69 21 76 42","06 74 94 09 90") -> 06 74 94 09 90 | V23: X | W23: X | Y23: 1.0327699 | AC23: Oui | AD23: Oui | AE23: Non
A24: 15843 | B24: Hangar Laurent ROUX | C24: 313.95 | D24: F2 DAVAI ENRSPV6 | E24: 44.92782 | F24: 2.98992 | G24: 10 Rue de Vareine 15260 Neuvéglise-sur-Truyère | H24: 15 | I24: Bâtiment à construire - A2 | J24: Yama Energies | K24: 45691 | L24: 45709 | M24: SOCOTEC POWER SERVICES | N24: 45713 | O24: 45769 | P24: DOMESOLAR NPA 3.45 | Q24: DMEGC-DM455M10RT-54HSW-HBW | R24: =_xlfn.XLOOKUP(Tableau2[[#This Row],[ID référent]],Feuil4!A:A,Feuil4!BD:BD) -> Parfait MEZEME ONA | S24: =IF(Tableau2[[#This Row],[Contact Chargé Exploitation]]="Parfait MEZEME ONA","06 63 06 94 73","06 74 09 71 44") -> 06 63 06 94 73 | T24: Jean-Paul THOROGOOD | U24: =IF(Tableau2[[#This Row],[Contact Gestion actif]]="Victor PONTAIS","06 69 21 76 42","06 74 94 09 90") -> 06 74 94 09 90 | W24: X | Y24: 0.95044437 | AC24: Oui | AD24: Oui | AE24: Non
A25: 90361 | B25: Serge Maltaverne | C25: 218.855 | D25: F3 DAVAI ENRSPV10 | E25: 46.6938 | F25: 4.10361 | G25: 638 Chard, 71320 Sainte-Radegonde, France | H25: 71 | I25: Toiture existante / Rénovation | J25: PROSUNFRANCE | K25: 45624 | L25: 45678 | M25: SOCOTEC POWER SERVICES | N25: 45693 | O25: 45799 | P25: DOMESOLAR NPA 3.45 | Q25: DMEGC-DM455M10RT-54HSW-HBW | R25: =_xlfn.XLOOKUP(Tableau2[[#This Row],[ID référent]],Feuil4!A:A,Feuil4!BD:BD) -> Yasser BADREZZAMANE | S25: =IF(Tableau2[[#This Row],[Contact Chargé Exploitation]]="Parfait MEZEME ONA","06 63 06 94 73","06 74 09 71 44") -> 06 74 09 71 44 | T25: Jean-Paul THOROGOOD | U25: =IF(Tableau2[[#This Row],[Contact Gestion actif]]="Victor PONTAIS","06 69 21 76 42","06 74 94 09 90") -> 06 74 94 09 90 | W25: X | Y25: 1.0325475 | AC25: Oui | AD25: Oui | AE25: Non
A26: 33559 | B26: Hangar Christophe CARRERE n°2 | C26: 278.005 | D26: F2 DAVAI ENRSPV7 | E26: 44.14804 | F26: 0.44966 | G26: Boy, 47600 Montagnac-sur-Auvignon, France | H26: 47 | I26: Bâtiment à construire - A1 | J26: Acrom | K26: 45642 | L26: 45747 | M26: SOCOTEC POWER SERVICES | N26: 45758 | O26: 45793 | P26: DOMESOLAR NPA 3.45 | Q26: DMEGC-DM455M10RT-B54HSW | R26: =_xlfn.XLOOKUP(Tableau2[[#This Row],[ID référent]],Feuil4!A:A,Feuil4!BD:BD) -> Parfait MEZEME ONA | S26: =IF(Tableau2[[#This Row],[Contact Chargé Exploitation]]="Parfait MEZEME ONA","06 63 06 94 73","06 74 09 71 44") -> 06 63 06 94 73 | T26: Victor PONTAIS | U26: =IF(Tableau2[[#This Row],[Contact Gestion actif]]="Victor PONTAIS","06 69 21 76 42","06 74 94 09 90") -> 06 69 21 76 42 | W26: X | Y26: 1.2212428 | AC26: Non | AD26: Oui | AE26: Non
A27: 95918 | B27: Hangar Frédéric CASTET | C27: 309.4 | D27: F2 DAVAI ENRSPV9 | E27: 43.043825 | F27: 0.859333 | G27: 11 Carrère de la Goutille, 31160 Estadens, France | H27: 31 | I27: Bâtiment à construire - C | J27: KEVEL | K27: 45719 | L27: 45741 | M27: BUREAU VERITAS | N27: 45750 | O27: 45803 | P27: DOMESOLAR NPA 3.45 | Q27: DMEGC-DM455M10RT-B54HSW | R27: =_xlfn.XLOOKUP(Tableau2[[#This Row],[ID référent]],Feuil4!A:A,Feuil4!BD:BD) -> Yasser BADREZZAMANE | S27: =IF(Tableau2[[#This Row],[Contact Chargé Exploitation]]="Parfait MEZEME ONA","06 63 06 94 73","06 74 09 71 44") -> 06 74 09 71 44 | T27: Victor PONTAIS | U27: =IF(Tableau2[[#This Row],[Contact Gestion actif]]="Victor PONTAIS","06 69 21 76 42","06 74 94 09 90") -> 06 69 21 76 42 | W27: X | Y27: 0.958312 | AC27: Oui | AD27: Oui | AE27: Non
A28: 95695 | B28: MARTEL 183 LOC | C28: 456.82 | D28: F2 DAVAI ENRSPV9 | E28: 46.212595 | F28: 1.6665264 | G28: LIEU-DIT LES RIBIERES LE GRAND BOURG | H28: 23 | I28: Toiture existante / Rénovation | J28: NEOXOM | K28: 45684 | L28: 45758 | M28: SOCOTEC POWER SERVICES | N28: 45723 | O28: 45743 | P28: DOMESOLAR NPA 3.45 | Q28: DMEGC-DM455M10RT-54HSW-HBW | R28: =_xlfn.XLOOKUP(Tableau2[[#This Row],[ID référent]],Feuil4!A:A,Feuil4!BD:BD) -> Parfait MEZEME ONA | S28: =IF(Tableau2[[#This Row],[Contact Chargé Exploitation]]="Parfait MEZEME ONA","06 63 06 94 73","06 74 09 71 44") -> 06 63 06 94 73 | T28: Victor PONTAIS | U28: =IF(Tableau2[[#This Row],[Contact Gestion actif]]="Victor PONTAIS","06 69 21 76 42","06 74 94 09 90") -> 06 69 21 76 42 | W28: X | Y28: 0.97029729 | AC28: Oui | AD28: Oui | AE28: Non
A29: 86550 | B29: Hangar Frederic Sinaud | C29: 499.59 | D29: F3 DAVAI ENRSPV11 | E29: 46.2183 | F29: 1.65147 | G29: 11 La Quaire, 23240 Saint-Priest-la-Plaine, France | H29: 23 | I29: Bâtiment à construire - C | J29: INNOVA | K29: 45684 | L29: 45716 | M29: SOCOTEC POWER SERVICES | N29: 45769 | O29: 45812 | P29: DOMESOLAR NPA 3.45 | Q29: DMEGC-DM455M10RT-54HSW-HBW | R29: =_xlfn.XLOOKUP(Tableau2[[#This Row],[ID référent]],Feuil4!A:A,Feuil4!BD:BD) -> Parfait MEZEME ONA | S29: =IF(Tableau2[[#This Row],[Contact Chargé Exploitation]]="Parfait MEZEME ONA","06 63 06 94 73","06 74 09 71 44") -> 06 63 06 94 73 | T29: Jean-Paul THOROGOOD | U29: =IF(Tableau2[[#This Row],[Contact Gestion actif]]="Victor PONTAIS","06 69 21 76 42","06 74 94 09 90") -> 06 74 94 09 90 | W29: X | Y29: 0.97393521 | AC29: Oui | AD29: Oui | AE29: Oui
A30: 90034 | B30: Hangar Frederic Sinaud | C30: 218.4 | D30: F3 DAVAI ENRSPV11 | E30: 46.23163 | F30: 1.52775 | G30: La Drable, 23300 Saint Priest la feuille | H30: 23 | I30: Bâtiment à construire - C | J30: INNOVA | K30: 45705 | L30: 45716 | M30: SOCOTEC POWER SERVICES | N30: 45769 | O30: 45812 | P30: DOMESOLAR NPA 3.45 | Q30: DMEGC-DM455M10RT-B54HSW | R30: =_xlfn.XLOOKUP(Tableau2[[#This Row],[ID référent]],Feuil4!A:A,Feuil4!BD:BD) -> Parfait MEZEME ONA | S30: =IF(Tableau2[[#This Row],[Contact Chargé Exploitation]]="Parfait MEZEME ONA","06 63 06 94 73","06 74 09 71 44") -> 06 63 06 94 73 | T30: Jean-Paul THOROGOOD | U30: =IF(Tableau2[[#This Row],[Contact Gestion actif]]="Victor PONTAIS","06 69 21 76 42","06 74 94 09 90") -> 06 74 94 09 90 | W30: X | Y30: 1.0085301 | AC30: Oui | AD30: Oui | AE30: Oui
A31: 90189 | B31: HARAS DE LA MAJORIE/MANOHA | C31: 499.59 | D31: F3 DAVAI ENRSPV10 | E31: 45.19709 | F31: 4.66906 | G31: L'Homme, 07790 Saint-Alban-d'Ay, France | H31: 7 | I31: Bâtiment à construire - C | J31: KEVEL | K31: 45726 | L31: 45758 | M31: SOCOTEC POWER SERVICES | N31: 45758 | O31: 45831 | P31: DOMESOLAR NPA 3.45 | Q31: DMEGC-DM455M10RT-54HSW-HBW | R31: =_xlfn.XLOOKUP(Tableau2[[#This Row],[ID référent]],Feuil4!A:A,Feuil4!BD:BD) -> Yasser BADREZZAMANE | S31: =IF(Tableau2[[#This Row],[Contact Chargé Exploitation]]="Parfait MEZEME ONA","06 63 06 94 73","06 74 09 71 44") -> 06 74 09 71 44 | T31: Jean-Paul THOROGOOD | U31: =IF(Tableau2[[#This Row],[Contact Gestion actif]]="Victor PONTAIS","06 69 21 76 42","06 74 94 09 90") -> 06 74 94 09 90 | W31: X | Y31: 1.0337699 | AC31: Oui | AD31: Oui | AE31: Non
A32: 99373 | B32: Hangar Yannick CLEMENT | C32: 331.24 | D32: F3 GIRASPV15 | E32: 43.04786 | F32: 0.85301 | G32: Gazailles, 31160 Estadens, France | H32: 31 | I32: Bâtiment à construire - C | J32: KEVEL | K32: 45733 | L32: 45761 | M32: BUREAU VERITAS | N32: 45775 | O32: 45800 | P32: DOMESOLAR NPA 3.45 | Q32: DMEGC-DM455M10RT-B54HSW | R32: =_xlfn.XLOOKUP(Tableau2[[#This Row],[ID référent]],Feuil4!A:A,Feuil4!BD:BD) -> Parfait MEZEME ONA | S32: =IF(Tableau2[[#This Row],[Contact Chargé Exploitation]]="Parfait MEZEME ONA","06 63 06 94 73","06 74 09 71 44") -> 06 63 06 94 73 | T32: Jean-Paul THOROGOOD | U32: =IF(Tableau2[[#This Row],[Contact Gestion actif]]="Victor PONTAIS","06 69 21 76 42","06 74 94 09 90") -> 06 74 94 09 90 | W32: X | Y32: 1.1032093 | AC32: Oui | AD32: Oui | AE32: Non
A33: 3384 | B33: Concept-TY Chambray 2 | C33: 118.37 | D33: F2 DAVAI ENRSPV7 | E33: 47.32796 | F33: 0.70112 | G33: Rue Etienne Cosson, 37170 Chambray-lès-Tours, France | H33: 37 | I33: Toiture existante / PV Ready | J33: REGIESOLAIRE | K33: 45614 | L33: 45744 | M33: SOCOTEC POWER SERVICES | N33: 45771 | O33: 45832 | P33: Soprasolar FixEvoTilt | Q33: JKM445N-54HL4R-V | R33: =_xlfn.XLOOKUP(Tableau2[[#This Row],[ID référent]],Feuil4!A:A,Feuil4!BD:BD) -> Yasser BADREZZAMANE | S33: =IF(Tableau2[[#This Row],[Contact Chargé Exploitation]]="Parfait MEZEME ONA","06 63 06 94 73","06 74 09 71 44") -> 06 74 09 71 44 | T33: Victor PONTAIS | U33: =IF(Tableau2[[#This Row],[Contact Gestion actif]]="Victor PONTAIS","06 69 21 76 42","06 74 94 09 90") -> 06 69 21 76 42 | W33: X | Y33: 0.96714355 | AC33: Oui | AD33: Oui | AE33: Non
A34: 35280 | B34: Hangar Patrick BLANCHET | C34: 159.25 | D34: F3 DAVAI ENRSPV14 | E34: 44.36059 | F34: 5.07619 | G34: Les Exclis, 26110 Venterol, France | H34: 26 | I34: Bâtiment à construire - C | J34: KEVEL | K34: 45775 | L34: 45789 | M34: SOCOTEC POWER SERVICES | N34: 45802 | O34: 45838 | P34: DOMESOLAR NPA 3.45 | Q34: DMEGC-DM455M10RT-B54HSW | R34: =_xlfn.XLOOKUP(Tableau2[[#This Row],[ID référent]],Feuil4!A:A,Feuil4!BD:BD) -> Yasser BADREZZAMANE | S34: =IF(Tableau2[[#This Row],[Contact Chargé Exploitation]]="Parfait MEZEME ONA","06 63 06 94 73","06 74 09 71 44") -> 06 74 09 71 44 | T34: Victor PONTAIS | U34: =IF(Tableau2[[#This Row],[Contact Gestion actif]]="Victor PONTAIS","06 69 21 76 42","06 74 94 09 90") -> 06 69 21 76 42 | W34: X | Y34: 0.94566271 | AC34: Oui | AD34: Oui | AE34: Non
A35: 3334 | B35: MATHIEU Vincent | C35: 218.4 | D35: F3 GIRASPV15 | E35: 43.24989 | F35: 2.64117 | G35: Lieu-dit Les Avals 11700 LA REDORTE | H35: 11 | I35: Bâtiment à construire - C | J35: KEVEL | K35: 45789 | L35: 45803 | M35: BUREAU VERITAS | N35: 45819 | O35: 45838 | P35: DOMESOLAR NPA 3.45 | Q35: DMEGC-DM455M10RT-B54HSW | R35: =_xlfn.XLOOKUP(Tableau2[[#This Row],[ID référent]],Feuil4!A:A,Feuil4!BD:BD) -> Yasser BADREZZAMANE | S35: =IF(Tableau2[[#This Row],[Contact Chargé Exploitation]]="Parfait MEZEME ONA","06 63 06 94 73","06 74 09 71 44") -> 06 74 09 71 44 | T35: Jean-Paul THOROGOOD | U35: =IF(Tableau2[[#This Row],[Contact Gestion actif]]="Victor PONTAIS","06 69 21 76 42","06 74 94 09 90") -> 06 74 94 09 90 | W35: X | Y35: 0.86722429 | Z35: Déclenchement AHCP récurrent | AC35: Oui | AD35: Oui | AE35: Non
A36: 82721 | B36: Cheraud | C36: 499.59 | D36: F3 DAVAI ENRSPV13 | E36: 47.355 | F36: -1.83701 | G36: Bellevue, 44260 Malville, France | H36: 44 | I36: Bâtiment à construire - A2 | J36: OFT | K36: 45748 | L36: 45775 | M36: SOCOTEC POWER SERVICES | N36: 45793 | O36: 45856 | P36: DOMESOLAR NPA 3.45 | Q36: DMEGC-DM455M10RT-B54HSW | R36: =_xlfn.XLOOKUP(Tableau2[[#This Row],[ID référent]],Feuil4!A:A,Feuil4!BD:BD) -> Parfait MEZEME ONA | S36: =IF(Tableau2[[#This Row],[Contact Chargé Exploitation]]="Parfait MEZEME ONA","06 63 06 94 73","06 74 09 71 44") -> 06 63 06 94 73 | T36: Jean-Paul THOROGOOD | U36: =IF(Tableau2[[#This Row],[Contact Gestion actif]]="Victor PONTAIS","06 69 21 76 42","06 74 94 09 90") -> 06 74 94 09 90 | W36: X | Y36: 1.0196579 | AC36: Oui | AD36: Oui | AE36: Non
A37: 95919 | B37: Hangar Frédéric CASTET | C37: 268.65 | D37: F3 DAVAI ENRSPV13 | E37: 43.043896 | F37: 0.859961 | G37: 11 carrère de la Gentille, ESTADENS, 31160 | H37: 31 | I37: Toiture existante / Rénovation | J37: NEOXOM | K37: 45769 | L37: 45785 | M37: BUREAU VERITAS | N37: 45750 | O37: 45803 | P37: DOMESOLAR NPA 3.45 | Q37: DMEGC-DM455M10RT-54HSW-HBW | R37: =_xlfn.XLOOKUP(Tableau2[[#This Row],[ID référent]],Feuil4!A:A,Feuil4!BD:BD) -> Yasser BADREZZAMANE | S37: =IF(Tableau2[[#This Row],[Contact Chargé Exploitation]]="Parfait MEZEME ONA","06 63 06 94 73","06 74 09 71 44") -> 06 74 09 71 44 | T37: Jean-Paul THOROGOOD | U37: =IF(Tableau2[[#This Row],[Contact Gestion actif]]="Victor PONTAIS","06 69 21 76 42","06 74 94 09 90") -> 06 74 94 09 90 | V37: X | W37: X | Y37: 0.94721199 | AC37: Non | AD37: Non | AE37: Non
A38: 32074 | B38: Didier - PRIEUR | C38: 499.59 | D38: F3 DAVAI ENRSPV10 | E38: 44.84159 | F38: 4.96118 | G38: Quartier de Montalivet 26120 Montmeyran | H38: 26 | I38: Bâtiment à construire - C | J38: KEVEL | K38: 45789 | L38: 45817 | M38: SOCOTEC POWER SERVICES | N38: 45831 | O38: 45862 | P38: DOMESOLAR NPA 3.45 | Q38: DMEGC-DM455M10RT-54HSW-HBW | R38: =_xlfn.XLOOKUP(Tableau2[[#This Row],[ID référent]],Feuil4!A:A,Feuil4!BD:BD) -> Yasser BADREZZAMANE | S38: =IF(Tableau2[[#This Row],[Contact Chargé Exploitation]]="Parfait MEZEME ONA","06 63 06 94 73","06 74 09 71 44") -> 06 74 09 71 44 | T38: Jean-Paul THOROGOOD | U38: =IF(Tableau2[[#This Row],[Contact Gestion actif]]="Victor PONTAIS","06 69 21 76 42","06 74 94 09 90") -> 06 74 94 09 90 | V38: X | W38: X | Y38: 0.95201209 | AC38: Oui | AD38: Oui | AE38: Non
A39: 95309 | B39: Hangar Eric LOGNON | C39: 324.87 | D39: F3 DAVAI ENRSPV11 | E39: 46.60446 | F39: 3.61907 | G39: Château des Millets, 03230 Chevagnes, France | H39: 3 | I39: Bâtiment à construire - A2 | J39: PROSUNFRANCE | K39: 45803 | L39: 45818 | M39: SOCOTEC POWER SERVICES | N39: 45821 | O39: 45863 | P39: DOMESOLAR NPA 3.45 | Q39: DMEGC-DM455M10RT-54HSW-HBW | R39: =_xlfn.XLOOKUP(Tableau2[[#This Row],[ID référent]],Feuil4!A:A,Feuil4!BD:BD) -> Yasser BADREZZAMANE | S39: =IF(Tableau2[[#This Row],[Contact Chargé Exploitation]]="Parfait MEZEME ONA","06 63 06 94 73","06 74 09 71 44") -> 06 74 09 71 44 | T39: Jean-Paul THOROGOOD | U39: =IF(Tableau2[[#This Row],[Contact Gestion actif]]="Victor PONTAIS","06 69 21 76 42","06 74 94 09 90") -> 06 74 94 09 90 | W39: X | Y39: 1.3386521 | AC39: Oui | AD39: Oui | AE39: Non
A40: 30516 | B40: Hangar LAMIOT | C40: 343.07 | D40: F3 DAVAI ENRSPV10 | E40: 45.73247 | F40: 4.2053 | G40: La Gélopière, 42110 Feurs, France | H40: 42 | I40: Bâtiment à construire - C | J40: PROSUNFRANCE | K40: 45712 | L40: 45819 | M40: SOCOTEC POWER SERVICES | N40: 45825 | O40: 45854 | P40: DOMESOLAR NPA 3.45 | Q40: DMEGC-DM455M10RT-B54HSW | R40: =_xlfn.XLOOKUP(Tableau2[[#This Row],[ID référent]],Feuil4!A:A,Feuil4!BD:BD) -> Yasser BADREZZAMANE | S40: =IF(Tableau2[[#This Row],[Contact Chargé Exploitation]]="Parfait MEZEME ONA","06 63 06 94 73","06 74 09 71 44") -> 06 74 09 71 44 | T40: Jean-Paul THOROGOOD | U40: =IF(Tableau2[[#This Row],[Contact Gestion actif]]="Victor PONTAIS","06 69 21 76 42","06 74 94 09 90") -> 06 74 94 09 90 | V40: X | W40: X | Y40: 0.99477332 | AC40: Oui | AD40: Oui | AE40: Non
...

Sheet Feuil4
A1: ID Pipedrive | B1: undefined | C1: Projet/SPV | D1: Date Mise en Service | E1: Adresse | F1: Code Postale | G1: Ville | H1: Contrat de bail | I1: Type de centrale | J1: Client | K1: Type de Contrat | L1: Numéro BTA | M1: Numéro CARD-I | N1: Nombre de PDL | O1: Numéro PRM | P1: Puissance crête (kWc) | Q1: Puissance maximale (kVA) | R1: Puissance souscrite (kVA) | S1: Productible P50 kWh/kWc/an | T1: Production P50 kWh/an | U1: Productible Variabilité P50 | V1: PR Go construction | W1: Productible Go Construction kWh/kWc | X1: Domaine de tension | Y1: Date Achat T0 | Z1: Tarif d'Achat (€/kWh) | AA1: Convention Tarif Essais | AB1: Contrat ACC | AC1: Acheteur | AD1: GRD | AE1: Surface modules (m²) | AF1: Latitude | AG1: Longitude | AH1: Financement | AI1: Mentions particulières | AJ1: Mainteneur | AK1: Nom complet du Client | AL1: Email principal du client | AM1: Email secondaire client | AN1: Téléphone principal client | AO1: Téléphone secondaire client | AP1: Installateur électrique | AQ1: Installateur structure | AR1: Loyer | AS1: Échéance | AT1: Echéance Année en cours | AU1: Type de Loyer | AV1: TVA Applicable | AW1: % du CA | AX1: Montant du Loyer fixe | AY1: Fréquence | AZ1: Loyer >20ans | BA1: Type de Loyer Post 20ans | BB1: % Du CA Post 20ans | BC1: Montant du Loyer fixe (>20ans) | BD1: Chargé d'Exploitation | BE1: Gestionnaire d'Actif | BF1: Chef de Projet | BG1: Chargé d'affaire | BH1: Reference Contrat Maintenance | BI1: Reference Contrat Developpement | BJ1: Reference Contrat O&M | BK1: Refacturation Girasole Services | BL1: Refacturation Télésurveillance F2 | BM1: Date Début Exploitation | BN1: Date PV Transfert en Exploitation signé | BO1: Date PV de fin de garantie de performance signé | BP1: Montant Pénalités EPC 1an | BQ1: Montant Pénalités Retard Contrat d'achat | BR1: Titulaire du Bail | BS1: Adresse Titulaire du Bail | BT1: Ville Titulaire du Bail | BU1: Code Postale Titulaire du Bail | BV1: SIREN (si applicable) | BW1: Date fin du Bail | BX1: Activité sous toiture | BY1: Date Début Contrat d'Achat OA | BZ1: Date fin du Contrat d'Achat OA | CA1: Date signature Contrat D'achat OA | CB1: Indexation du Loyer | CC1: Type d'élément | CD1: Chemin d'accès
A2: 3338 | B2: CHEVRIER | C2: DAVAI ENRSPV10 | D2: 45959 | E2: 712 Rue de la Croix de Romont | F2: 88390 | G2: Darnieulles | H2: BaC | I2: Toiture inclinée | J2: Agriculteur | K2: S21 | L2: BTA1200149 | M2: 9818700 | N2: 1 | O2: 50095153915292 | P2: 318.5 | Q2: 250 | R2: 249 | S2: 1156 | T2: 368186 | U2: 0.054 | V2: 0.86647242 | W2: 1136.6797 | X2: BT | Y2: 45314 | Z2: 0.1208 | AA2: FALSE | AB2: FALSE | AC2: EDF OA | AD2: ENEDIS | AE2: 1398.676 | AF2: 48.19827 | AG2: 6.33986 | AH2: N°3 - Kyoto (SPV 10,13 &14) | AI2: Mot de passe onduleur : 0000000a | AJ2: EIFFAGE | AK2: THOMAS CHEVRIER | AL2: gaecdallonzy@laposte.net | AN2: +33619062549 | AP2: VOLTISSIMA | AQ2: CANCE | AR2: FALSE | AV2: FALSE | AZ2: FALSE | BD2: Yasser BADREZZAMANE | BE2: Johan LAGARDE | BF2: Ibtissam ABSSI | BG2: Sébastien GUYOUX | BH2: MTN-CONT-004-Contrat_EIFFAGE_maintenance_PV_BT-001 | BI2: DEV-CONT-SPV010-Contrat_DEV_EPC_DAVAI_ENR-1 | BJ2: EX-CONT-SPV010-Contrat_Suivi_O&M_Gestion_Actifs_DAVAI_ENR-1 | BK2: 856 | BL2: 188.2895 | BX2: Stockage matériel + fourrage | CB2: FALSE | CC2: Élément | CD2: sites/ServiceOM-AssetManagement/Lists/Exploitation Data Centrale
A3: 98570 | B3: LATREILLE | C3: DAVAI ENRSPV14 | D3: 45958 | E3: Vaurs | F3: 19430 | G3: Sexcles | H3: BE | I3: Toiture inclinée | J3: Agriculteur | K3: S21 | L3: BTA1110971 | M3: 9255850 | N3: 1 | O3: 50031335405373 | P3: 352.17 | Q3: 280 | R3: 249 | S3: 1179.6 | T3: 415419.73 | U3: 0.054 | V3: 0.878 | W3: 1179.6 | X3: BT | Y3: 45161 | Z3: 0.1238 | AA3: FALSE | AB3: FALSE | AC3: EDF OA | AD3: ENEDIS | AE3: 1546.536 | AF3: 45.02811 | AG3: 2.02617 | AH3: N°3 - Kyoto (SPV 10,13 &14) | AI3: RAS | AJ3: EIFFAGE | AK3: Didier LATREILLE | AL3: didierlatreille0263@orange.fr | AN3: +33682109080 | AP3: 3C INSTAL | AQ3: BIOTECK | AR3: FALSE | AV3: FALSE | AZ3: FALSE | BD3: Parfait MEZEME ONA | BE3: Victor PONTAIS | BF3: Martin DE GUERRE | BG3: Alexandre COL | BH3: MTN-CONT-004-Contrat_EIFFAGE_maintenance_PV_BT-001 | BI3: DEV-CONT-SPV014_Contrat_DEV_EPC_DAVAI_ENR-1 (signed) (1) | BJ3: EX-CONT-SPV014-Contrat_Suivi_OM_Gestion_Actifs_DAVAI -ENR-01 (1) | BK3: 856 | BL3: 200.64639 | BX3: stabulation et stockage | CB3: FALSE | CC3: Élément | CD3: sites/ServiceOM-AssetManagement/Lists/Exploitation Data Centrale
A4: 99025 | B4: GARRELOU | C4: DAVAI ENRSPV14 | D4: 45958 | E4: Les Trieux | F4: 19220 | G4: Bassignac-le-Haut | H4: BE | I4: Toiture inclinée | J4: Agriculteur | K4: S21 | L4: BTA1160782 | M4: 9292350 | N4: 1 | O4: 50004127237174 | P4: 191 | Q4: 170 | R4: 146 | S4: 1164 | T4: 222324 | U4: 0.0504 | V4: 0.874 | W4: 1170 | X4: BT | Y4: 45250 | Z4: 0.1208 | AA4: FALSE | AB4: FALSE | AC4: EDF OA | AD4: ENEDIS | AE4: 837 | AF4: 45.19779 | AG4: 2.09035 | AH4: N°3 - Kyoto (SPV 10,13 &14) | AI4: RAS | AJ4: EIFFAGE | AK4: Romain Garrelou | AL4: romain.garrelou@hotmail.com | AN4: +33 6 37 24 67 62 | AP4: NEOXOM | AQ4: ACC | AR4: FALSE | AV4: FALSE | AZ4: FALSE | BD4: Parfait MEZEME ONA | BE4: Victor PONTAIS | BF4: Martin DE GUERRE | BG4: Alexandre COL | BH4: MTN-CONT-004-Contrat_EIFFAGE_maintenance_PV_BT-001 | BI4: DEV-CONT-SPV014_Contrat_DEV_EPC_DAVAI_ENR-1 (signed) (1) | BJ4: EX-CONT-SPV014-Contrat_Suivi_OM_Gestion_Actifs_DAVAI -ENR-01 (1) | BK4: 856 | BL4: 141.497 | BX4: Stabulation + Stockage Fourrage | CB4: FALSE | CC4: Élément | CD4: sites/ServiceOM-AssetManagement/Lists/Exploitation Data Centrale
A5: 99131 | B5: LANNES | C5: GIRASPV16 | D5: 45957 | E5: Lieu-dit Mamour | F5: 11270 | G5: La Cassaigne | H5: BaC | I5: Toiture inclinée | J5: Agriculteur | K5: S21 | L5: BTA1269517 | M5: 9622450 | N5: 1 | O5: 50018307634341 | P5: 308 | Q5: 248 | R5: 248 | S5: 1182 | T5: 364056 | U5: 0.054 | V5: 0.8611 | W5: 1230.02 | X5: BT | Y5: 45425 | Z5: 0.1118 | AA5: FALSE | AB5: FALSE | AC5: EDF OA | AD5: ENEDIS | AE5: 1351 | AF5: 43.18474 | AG5: 1.99512 | AH5: N°4 | AI5: RAS | AJ5: EIFFAGE | AK5: Quentin LANNES | AL5: earlbds@gmail.com | AN5: +33630546473 | AP5: KEVEL | AQ5: MOMSTEEL | AR5: FALSE | AV5: FALSE | AZ5: FALSE | BD5: Parfait MEZEME ONA | BE5: Victor PONTAIS | BF5: Charbel BOUZERDAN | BG5: Gabriel AYMA | BH5: MTN-CONT-004-Contrat_EIFFAGE_maintenance_PV_BT-001 | BI5: DEV-CONT-SPV016_Contrat_DEV_EPC_DAVAI_ENR-1 | BJ5: EX-CONT-SPV016-Contrat_Suivi_OM_Gestion_Actifs_DAVAI -ENR-01 | BK5: 856 | BL5: 184.436 | BX5: Stockage matériels et légumes | CB5: FALSE | CC5: Élément | CD5: sites/ServiceOM-AssetManagement/Lists/Exploitation Data Centrale
A6: 3427 | B6: ESCOULA | C6: DAVAI ENRSPV14 | D6: 45957 | E6: Trouley | F6: 65140 | G6: Trouley-Labarthe | H6: BaC | I6: Toiture inclinée | J6: Agriculteur | K6: S21 | L6: BTA1204745|BTA1204781 | M6: 9683200|9702850 | N6: 2 | O6: 50018019831551|50010783941577 | P6: 500 | Q6: 500 | R6: 408 | S6: 1181.5 | T6: 590750 | U6: 0.054 | V6: 0.877 | W6: 1178.2 | X6: BT | Y6: 45327 | Z6: 0.117 | AA6: FALSE | AB6: FALSE | AC6: EDF OA | AD6: ENEDIS | AE6: 2194 | AF6: 43.31659 | AG6: 0.24262 | AH6: N°3 - Kyoto (SPV 10,13 &14) | AI6: RAS | AJ6: EIFFAGE | AK6: Thierry ESCOULA | AL6: thierry.escoula1@orange.fr | AN6: +33678642764 | AP6: ACROM | AQ6: GIRAUD | AR6: FALSE | AV6: FALSE | AZ6: FALSE | BD6: Parfait MEZEME ONA | BE6: Victor PONTAIS | BF6: Gwendal HART | BG6: Victor REVUELTA | BH6: MTN-CONT-004-Contrat_EIFFAGE_maintenance_PV_BT-001 | BI6: DEV-CONT-SPV014_Contrat_DEV_EPC_DAVAI_ENR-1 (signed) (1) | BJ6: EX-CONT-SPV014-Contrat_Suivi_OM_Gestion_Actifs_DAVAI -ENR-01 (1) | BK6: 856 | BL6: 254.9 | BX6: Ovins, Bovins, matériel et fourrage | CB6: FALSE | CC6: Élément | CD6: sites/ServiceOM-AssetManagement/Lists/Exploitation Data Centrale
A7: 95955 | B7: CONSOLI | C7: DAVAI ENRSPV13 | D7: 45953 | E7: Rte de l'Escauderie | F7: 24130 | G7: Prigonrieux | H7: BaC | I7: Toiture inclinée | J7: Agriculteur | K7: S21 | L7: BTA1141881 | M7: 8961150 | N7: 1 | O7: 50060857585907 | P7: 319 | Q7: 249 | R7: 249 | S7: 1145 | T7: 365255 | U7: 0.054 | V7: 0.8654 | W7: 1144.11 | X7: BT | Y7: 45216 | Z7: 0.1238 | AA7: FALSE | AB7: FALSE | AC7: EDF OA | AD7: ENEDIS | AE7: 1399 | AF7: 44.85555 | AG7: 0.43414 | AH7: N°3 - Kyoto (SPV 10,13 &14) | AI7: RAS | AJ7: EIFFAGE | AK7: CONSOLI | AL7: consoli.et.fils@wanadoo.fr | AN7: +33689273405 | AP7: ACROM | AQ7: MOMSTEEL | AR7: FALSE | AV7: FALSE | AZ7: FALSE | BD7: Parfait MEZEME ONA | BE7: Johan LAGARDE | BF7: Gwendal HART | BG7: Victor REVUELTA | BH7: MTN-CONT-004-Contrat_EIFFAGE_maintenance_PV_BT-001 | BI7: DEV-CONT-SPV013-Contrat_DEV_EPC_DAVAI_ENR-1 | BJ7: EX-CONT-SPV013-Contrat_Suivi_OM_Gestion_Actifs_DAVAI -ENR-01 | BK7: 856 | BL7: 188.473 | BX7: Stockage de camions + stockage de matériel | CB7: FALSE | CC7: Élément | CD7: sites/ServiceOM-AssetManagement/Lists/Exploitation Data Centrale
A8: 33087 | B8: BAILLY | C8: DAVAI ENRSPV10 | D8: 45952 | E8: La Cave | F8: 03230 | G8: Garnat-sur-Engièvre | H8: BaC | I8: Toiture inclinée | J8: Agriculteur | K8: S21 | L8: BTA1038999 | BTA1038997 | M8: 9124750 | 9085000 | N8: 2 | O8: 50048702663389 | 50063174443341 | P8: 499.59 | Q8: 440 | R8: 417.6 | S8: 1209 | T8: 604004.31 | U8: 0.054 | V8: 0.8761 | W8: 1191.44 | X8: BT | Y8: 45036 | Z8: 0.1312 | AA8: FALSE | AB8: FALSE | AC8: EDF OA | AD8: ENEDIS | AE8: 2193.922 | AF8: 46.64674 | AG8: 3.67873 | AH8: N°3 - Kyoto (SPV 10,13 &14) | AI8: Mot de passe onduleur : Exploitation2023 | AJ8: EIFFAGE | AK8: Matthieu BAILLY | AL8: mouss.bailly@wanadoo.fr | AN8: +33672402650 | AO8: +33248721293 | AP8: PROSUNFRANCE | AQ8: CRAI + EMCB | AR8: FALSE | AV8: FALSE | AZ8: FALSE | BD8: Yasser BADREZZAMANE | BE8: Johan LAGARDE | BF8: Nicolas PETROPAVLOVSKY | BG8: Sébastien GUYOUX | BH8: MTN-CONT-004-Contrat_EIFFAGE_maintenance_PV_BT-001 | BI8: DEV-CONT-SPV010-Contrat_DEV_EPC_DAVAI_ENR-1 | BJ8: EX-CONT-SPV010-Contrat_Suivi_O&M_Gestion_Actifs_DAVAI_ENR-1 | BK8: 856 | BL8: 254.74953 | BX8: Stockage matériel (44%), fourrage de paille (44%), animaux (12%) | CB8: FALSE | CC8: Élément | CD8: sites/ServiceOM-AssetManagement/Lists/Exploitation Data Centrale
A9: 3405 | B9: GROS | C9: GIRASPV17 | D9: 45952 | E9: 1892 Chem. des Brugues | F9: 82370 | G9: Nohic | H9: BaC | I9: Toiture inclinée | J9: Agriculteur | K9: S21 | L9: BTA1163927 | M9: 9669500 | N9: 1 | O9: 50094286186899 | P9: 264 | Q9: 220 | R9: 220 | S9: 1258 | T9: 332112 | U9: 0.054 | V9: 0.8854 | W9: 1258 | X9: BT | Y9: 45252 | Z9: 0.1208 | AA9: FALSE | AB9: FALSE | AC9: EDF OA | AD9: ENEDIS | AE9: 1159 | AF9: 43.87073 | AG9: 1.43036 | AH9: N°4 | AI9: RAS | AJ9: EIFFAGE | AK9: Véronique GROS | AL9: marc.blavette@wanadoo.fr | AN9: +33603293138 | AP9: Non indiqué | AQ9: MOMSTEEL | AR9: FALSE | AV9: FALSE | AZ9: FALSE | BD9: Parfait MEZEME ONA | BE9: Johan LAGARDE | BF9: Gwendal HART | BG9: Nicolas CADENE | BH9: MTN-CONT-004-Contrat_EIFFAGE_maintenance_PV_BT-001 | BI9: DEV-CONT-SPV017_Contrat_DEV_EPC_DAVAI_ENR-1 | BJ9: EX-CONT-SPV017-Contrat_Suivi_OM_Gestion_Actifs_DAVAI -ENR-01 | BK9: 856 | BL9: 168.288 | BX9: Rond de Ionge + boxes à chevaux/Stockage de matériel/Stockage de paille, foin et fourrage | CB9: FALSE | CC9: Élément | CD9: sites/ServiceOM-AssetManagement/Lists/Exploitation Data Centrale
A10: 99375 | B10: CLEMENT | C10: DAVAI ENRSPV14 | D10: 45951 | E10: 6 Gouterouch | F10: 31160 | G10: Estadens | H10: BE | I10: Toiture inclinée | J10: Agriculteur | K10: S21 | L10: BTA1144036 | M10: 9881650 | N10: 1 | O10: 50092984346706 | P10: 106 | Q10: 99 | R10: 99 | S10: 1175 | T10: 124550 | U10: 0.054 | V10: 0.8509 | W10: 1175 | X10: BT | Y10: 45226 | Z10: 0.1238 | AA10: FALSE | AB10: FALSE | AC10: EDF OA | AD10: ENEDIS | AE10: 468 | AF10: 43.0483 | AG10: 0.8525 | AH10: N°3 - Kyoto (SPV 10,13 &14) | AI10: RAS | AJ10: EIFFAGE | AK10: Yannick CLEMENT | AL10: clement.yannick31@gmail.com | AN10: +33610332718 | AP10: NEOXOM | AQ10: ACC | AR10: FALSE | AV10: FALSE | AZ10: FALSE | BD10: Parfait MEZEME ONA | BE10: Victor PONTAIS | BF10: Gwendal HART | BG10: Nicolas CADENE | BH10: MTN-CONT-004-Contrat_EIFFAGE_maintenance_PV_BT-001 | BI10: DEV-CONT-SPV014_Contrat_DEV_EPC_DAVAI_ENR-1 (signed) (1) | BJ10: EX-CONT-SPV014-Contrat_Suivi_OM_Gestion_Actifs_DAVAI -ENR-01 (1) | BK10: 856 | BL10: 110.302 | BX10: Stabulation | CB10: FALSE | CC10: Élément | CD10: sites/ServiceOM-AssetManagement/Lists/Exploitation Data Centrale
A11: 95611 | B11: TOUCHAIS | C11: DAVAI ENRSPV13 | D11: 45946 | E11: 3 Joffre | F11: 33580 | G11: Le Puy | H11: BaC | I11: Toiture inclinée | J11: Agriculteur | K11: S21 | L11: BTA1209116 | M11: 9030700 | N11: 1 | O11: 50055501601691 | P11: 309 | Q11: 249 | R11: 249 | S11: 1166 | T11: 360294 | U11: 0.054 | V11: 0.8685 | W11: 1159.9 | X11: BT | Y11: 45335 | Z11: 0.1174 | AA11: FALSE | AB11: FALSE | AC11: EDF OA | AD11: ENEDIS | AE11: 1359 | AF11: 44.655162 | AG11: 0.049253 | AH11: N°3 - Kyoto (SPV 10,13 &14) | AI11: RAS | AJ11: EIFFAGE | AK11: Benoit TOUCHAIS | AL11: elevage.touchais33@gmail.com | AN11: +33674642000 | AP11: OFT | AQ11: CANCE | AR11: FALSE | AV11: FALSE | AZ11: FALSE | BD11: Parfait MEZEME ONA | BE11: Johan LAGARDE | BF11: Ibtissam ABSSI | BG11: Victor REVUELTA | BH11: MTN-CONT-004-Contrat_EIFFAGE_maintenance_PV_BT-001 | BI11: DEV-CONT-SPV013-Contrat_DEV_EPC_DAVAI_ENR-1 | BJ11: EX-CONT-SPV013-Contrat_Suivi_OM_Gestion_Actifs_DAVAI -ENR-01 | BK11: 856 | BL11: 184.803 | BX11: Stockage de matériel agricole + fourrage + céréales | CB11: FALSE | CC11: Élément | CD11: sites/ServiceOM-AssetManagement/Lists/Exploitation Data Centrale
A12: 95610 | B12: TOUCHAIS | C12: GIRASPV16 | D12: 45946 | E12: 3 Joffre | F12: 33580 | G12: Le Puy | H12: BaC | I12: Toiture inclinée | J12: Agriculteur | K12: S21 | L12: BTA1209125|BTA1208955 | M12: 8895850|8895950 | N12: 2 | O12: 50054199141585|50019322151607 | P12: 499 | Q12: 440 | R12: 410 | S12: 1254 | T12: 625746 | U12: 0.054 | V12: 0.8382 | W12: 1214.89 | X12: BT | Y12: 45335 | Z12: 0.117 | AA12: FALSE | AB12: FALSE | AC12: EDF OA | AD12: ENEDIS | AE12: 2194 | AF12: 44.65593 | AG12: 0.04986 | AH12: N°4 | AI12: RAS | AJ12: EIFFAGE | AK12: Benoit TOUCHAIS | AL12: elevage.touchais33@gmail.com | AN12: +33674642000 | AP12: OFT | AQ12: CANCE | AR12: FALSE | AV12: FALSE | AZ12: FALSE | BD12: Parfait MEZEME ONA | BE12: Victor PONTAIS | BF12: Ibtissam ABSSI | BG12: Victor REVUELTA | BH12: MTN-CONT-004-Contrat_EIFFAGE_maintenance_PV_BT-001 | BI12: DEV-CONT-SPV016_Contrat_DEV_EPC_DAVAI_ENR-1 | BJ12: EX-CONT-SPV016-Contrat_Suivi_OM_Gestion_Actifs_DAVAI -ENR-01 | BK12: 856 | BL12: 254.533 | BX12: Stabulation, stockage de matériel, stockage de céréales et stockage de fourrage + Laiterie | CB12: FALSE | CC12: Élément | CD12: sites/ServiceOM-AssetManagement/Lists/Exploitation Data Centrale
A13: 94563 | B13: GAILLARD | C13: DAVAI ENRSPV13 | D13: 45945 | E13: Le Ménial | F13: 43170 | G13: Venteuges | H13: BE | I13: Toiture inclinée | J13: Agriculteur | K13: S21 | L13: BTA1033678| | M13: 8534450|8532950 | N13: 2 | O13: 50079383380103|50072147490146 | P13: 386 | Q13: 370 | R13: 330 | S13: 1148.5 | T13: 443321 | U13: 0.054 | V13: 0.8818 | W13: 1165.76 | X13: BT | Y13: 44767 | Z13: 0.1312 | AA13: FALSE | AB13: FALSE | AC13: EDF OA | AD13: ENEDIS | AE13: 1696 | AF13: 44.97237 | AG13: 3.50346 | AH13: N°3 - Kyoto (SPV 10,13 &14) | AI13: RAS | AJ13: EIFFAGE | AK13: Franck GAILLARD | AL13: franckgaillard43@orange.fr | AN13: +33608672385 | AO13: +33608672384 | AP13: PROSUNFRANCE | AQ13: PROSUNFRANCE | AR13: FALSE | AV13: FALSE | AZ13: FALSE | BD13: Parfait MEZEME ONA | BE13: Johan LAGARDE | BF13: Stéphane Vialettes | BG13: Alexandre COL | BH13: MTN-CONT-004-Contrat_EIFFAGE_maintenance_PV_BT-001 | BI13: DEV-CONT-SPV013-Contrat_DEV_EPC_DAVAI_ENR-1 | BJ13: EX-CONT-SPV013-Contrat_Suivi_OM_Gestion_Actifs_DAVAI -ENR-01 | BK13: 856 | BL13: 213.062 | BX13: Stabulation | CB13: FALSE | CC13: Élément | CD13: sites/ServiceOM-AssetManagement/Lists/Exploitation Data Centrale
A14: 99435 | B14: ROQUEFORT | C14: DAVAI ENRSPV14 | D14: 45943 | E14: Le Coustalou | F14: 12300 | G14: Livinhac-le-Haut | H14: BE | I14: Toiture inclinée | J14: Agriculteur | K14: S21 | L14: BTA1112191 | M14: 9610550 | N14: 1 | O14: 50030177229112 | P14: 345 | Q14: 249 | R14: 249 | S14: 1182 | T14: 407790 | U14: 0.054 | V14: 0.875 | W14: 1191.5 | X14: BT | Y14: 45163 | Z14: 0.1238 | AA14: FALSE | AB14: FALSE | AC14: EDF OA | AD14: ENEDIS | AE14: 1517 | AF14: 44.59297 | AG14: 2.22688 | AH14: N°3 - Kyoto (SPV 10,13 &14) | AI14: RAS | AJ14: EIFFAGE | AK14: Cédric ROQUEFORT | AL14: cedric.roquefort@orange.fr | AN14: 06 72 89 77 57 | AP14: YAMA ENERGIES | AQ14: BIOTECK | AR14: TRUE | AS14: 46022 | AT14: 46022 | AU14: Fixe Indexé | AV14: FALSE | AX14: 4312.5 | AY14: Annuelle | AZ14: TRUE | BA14: fixe | BD14: Parfait MEZEME ONA | BE14: Victor PONTAIS | BF14: Martin DE GUERRE | BG14: Nicolas CADENE | BH14: MTN-CONT-004-Contrat_EIFFAGE_maintenance_PV_BT-001 | BI14: DEV-CONT-SPV014_Contrat_DEV_EPC_DAVAI_ENR-1 (signed) (1) | BJ14: EX-CONT-SPV014-Contrat_Suivi_OM_Gestion_Actifs_DAVAI -ENR-01 (1) | BK14: 856 | BL14: 198.015 | BX14: Stabulation et stockage | CB14: TRUE | CC14: Élément | CD14: sites/ServiceOM-AssetManagement/Lists/Exploitation Data Centrale
A15: 83798 | B15: MORELLO | C15: DAVAI ENRSPV12 | D15: 45938 | E15: Mas Thibert | F15: 13104 | G15: Arles | H15: BaC;#BE | I15: Toiture inclinée | J15: Agriculteur | K15: S21 | L15: BTA0981875 | M15: 8006450 | N15: 1 | O15: 50019619044477 | P15: 339.47 | Q15: 330 | R15: 249.9 | S15: 1335 | T15: 453192.45 | U15: 0.053 | V15: 0.844 | W15: 1321.4 | X15: BT | Y15: 44762 | Z15: 0.1287 | AA15: FALSE | AB15: FALSE | AC15: EDF OA | AD15: ENEDIS | AE15: 1597.348 | AF15: 43.64061 | AG15: 4.55457 | AH15: N°2 - Finergreen - Construction 2023 | AI15: 2 Bâtiments BAC + BE | AJ15: EIFFAGE | AK15: Anna MORELLO | AL15: anna.marello@hotmail.fr | AN15: +33621844296 | AO15: +393339690030 | AP15: HBBAT | AQ15: HBBAT | AR15: FALSE | AV15: FALSE | AZ15: FALSE | BD15: Yasser BADREZZAMANE | BE15: Jean-Paul THOROGOOD | BF15: Charbel BOUZERDAN | BG15: Hilal KAAOUANA | BH15: MTN-CONT-004-Contrat_EIFFAGE_maintenance_PV_BT-001 | BI15: DEV-CONT-SPV012-Contrat_DEV_EPC_DAVAI_ENR-1 | BJ15: EX-CONT-SPV012-Contrat_Suivi_O&M_Gestion_Actifs_DAVAI_ENR-1 | BK15: 856 | BL15: 189.68549 | BX15: stockage de matériel/foin et fourrage | CB15: FALSE | CC15: Élément | CD15: sites/ServiceOM-AssetManagement/Lists/Exploitation Data Centrale
A16: 94565 | B16: GAUDON | C16: DAVAI ENRSPV10 | D16: 45937 | E16: La Garenne | F16: 03500 | G16: Meillard | H16: BaC | I16: Toiture inclinée | J16: Agriculteur | K16: S21 | L16: BTA0957900 | BTA | M16: 8683600 | 9010700 | N16: 2 | O16: 50074030875808 | 50088502655851 | P16: 499.59 | Q16: 440 | R16: 440 | S16: 1222.432 | T16: 610714.8 | U16: 0.054 | V16: 0.8721 | W16: 964.48 | X16: BT | Y16: 44853 | Z16: 0.1312 | AA16: FALSE | AB16: FALSE | AC16: EDF OA | AD16: ENEDIS | AE16: 2193.923 | AF16: 46.37657 | AG16: 3.25555 | AH16: N°3 - Kyoto (SPV 10,13 &14) | AI16: Mot de passe onduleur : Exploitation2023 | AJ16: EIFFAGE | AK16: DAMIEN GAUDON | AL16: gaudon.damien@gmail.com | AN16: +33625052624 | AP16: PROSUNFRANCE | AQ16: CANCE | AR16: FALSE | AV16: FALSE | AZ16: FALSE | BD16: Yasser BADREZZAMANE | BE16: Johan LAGARDE | BF16: Charbel BOUZERDAN | BG16: Sébastien GUYOUX | BH16: MTN-CONT-004-Contrat_EIFFAGE_maintenance_PV_BT-001 | BI16: DEV-CONT-SPV010-Contrat_DEV_EPC_DAVAI_ENR-1 | BJ16: EX-CONT-SPV010-Contrat_Suivi_O&M_Gestion_Actifs_DAVAI_ENR-1 | BK16: 856 | BL16: 254.74953 | BX16: stockage de matériel/stabulation/foin et fourrage | CB16: FALSE | CC16: Élément | CD16: sites/ServiceOM-AssetManagement/Lists/Exploitation Data Centrale
A17: 97678 | B17: CORREDERA | C17: DAVAI ENRSPV10 | D17: 45936 | E17: 89 Route Serre d'Odun | F17: 31420 | G17: Cassagnabère-Tournas | H17: BE | I17: Toiture inclinée | J17: Agriculteur | K17: S21 | L17: BTA1021666 | M17: 9403500 | N17: 1 | O17: 50090238172678 | P17: 209 | Q17: 175 | R17: 175 | S17: 1187.63 | T17: 248214.67 | U17: 0.054 | V17: 0.8755 | W17: 1187.63 | X17: BT | Y17: 45007 | Z17: 0.1312 | AA17: FALSE | AB17: FALSE | AC17: EDF OA | AD17: ENEDIS | AE17: 919 | AF17: 43.21504 | AG17: 0.77149 | AH17: N°3 - Kyoto (SPV 10,13 &14) | AI17: RAS | AJ17: EIFFAGE | AK17: Richard CORREDERA | AL17: richard.corredera@rc-trans.com | AN17: 0622657255 | AP17: KEVEL | AQ17: SO | AR17: FALSE | AV17: FALSE | AZ17: FALSE | BD17: Parfait MEZEME ONA | BE17: Johan LAGARDE | BF17: Gwendal HART | BG17: Nicolas CADENE | BH17: MTN-CONT-004-Contrat_EIFFAGE_maintenance_PV_BT-001 | BI17: DEV-CONT-SPV010-Contrat_DEV_EPC_DAVAI_ENR-1 | BJ17: EX-CONT-SPV010-Contrat_Suivi_O&M_Gestion_Actifs_DAVAI_ENR-1 | BK17: 856 | BL17: 148.103 | BX17: Stockage matériel agricole | CB17: FALSE | CC17: Élément | CD17: sites/ServiceOM-AssetManagement/Lists/Exploitation Data Centrale
A18: 3365 | B18: CHARTRAIN | C18: GIRASPV15 | D18: 45932 | E18: La Touche | F18: 72330 | G18: Oizé | H18: BaC | I18: Toiture inclinée | J18: Agriculteur | K18: S21 | L18: BTA1200960 | M18: 9657300 | N18: 1 | O18: 50005284403392 | P18: 320.32 | Q18: 250 | R18: 247 | S18: 1198 | T18: 383743.36 | U18: 0.054 | V18: 0.876 | W18: 1190.1 | X18: BT | Y18: 45313 | Z18: 0.1209 | AA18: FALSE | AB18: FALSE | AC18: EDF OA | AD18: ENEDIS | AE18: 1406.668 | AF18: 47.80672 | AG18: 0.1157 | AH18: N°3 - Fuji (SPV 11&15) | AI18: RAS | AJ18: EIFFAGE | AK18: Florian CHARTRAIN | AL18: lapetiteboulas@orange.fr | AN18: +33658126588 | AP18: INNOVA | AQ18: BARBOT | AR18: FALSE | AV18: FALSE | AZ18: FALSE | BD18: Yasser BADREZZAMANE | BE18: Jean-Paul THOROGOOD | BF18: Ibtissam ABSSI | BG18: Loïc GUILLEUX | BH18: MTN-CONT-004-Contrat_EIFFAGE_maintenance_PV_BT-001 | BI18: DEV-CONT-SPV015_Contrat_DEV_EPC_DAVAI_ENR-1 (signed) (1) | BJ18: EX-CONT-SPV015-Contrat_Suivi_OM_Gestion_Actifs_DAVAI -ENR-01 | BK18: 856 | BL18: 188.95744 | BX18: Stockage matériel, fourrage et paille | CB18: FALSE | CC18: Élément | CD18: sites/ServiceOM-AssetManagement/Lists/Exploitation Data Centrale
A19: 94568 | B19: BOUILLET | C19: DAVAI ENRSPV13 | D19: 45932 | E19: Les Quatre Vents | F19: 03470 | G19: Saligny-sur-Roudon | H19: BaC | I19: Toiture inclinée | J19: Agriculteur | K19: S21 | L19: BTA0962241 | BTA0961960 | M19: 9086750 | 9250450 | N19: 2 | O19: 50001672415830 | 50087200635771 | P19: 499.59 | Q19: 440 | R19: 440 | S19: 1200.6593 | T19: 599837.38 | U19: 0.054 | V19: 0.874 | W19: 1210.83 | X19: BT | Y19: 44869 | Z19: 0.1311 | AA19: FALSE | AB19: FALSE | AC19: EDF OA | AD19: ENEDIS | AE19: 2193.92 | AF19: 46.47175 | AG19: 3.77821 | AH19: N°3 - Kyoto (SPV 10,13 &14) | AI19: Mot de passe onduleur : Exploitation2023 | AJ19: EIFFAGE | AK19: FABRICE BOUILLET | AL19: fabrice.bouillet70@gmail.com | AN19: +33676318305 | AP19: PROSUNFRANCE | AQ19: CANCE | AR19: FALSE | AV19: FALSE | AZ19: FALSE | BD19: Yasser BADREZZAMANE | BE19: Johan LAGARDE | BF19: Charbel BOUZERDAN | BG19: Sébastien GUYOUX | BH19: MTN-CONT-004-Contrat_EIFFAGE_maintenance_PV_BT-001 | BI19: DEV-CONT-SPV013-Contrat_DEV_EPC_DAVAI_ENR-1 | BJ19: EX-CONT-SPV013-Contrat_Suivi_OM_Gestion_Actifs_DAVAI -ENR-01 | BK19: 856 | BL19: 254.74953 | BX19: stockage de matériel/stabulation/foin et fourrage | CB19: FALSE | CC19: Élément | CD19: sites/ServiceOM-AssetManagement/Lists/Exploitation Data Centrale
A20: 93459 | B20: GUENIOT | C20: GIRASPV15 | D20: 45931 | E20: ZA Volzac | F20: 15100 | G20: Saint-Flour | H20: BaC | I20: Toiture inclinée | J20: Tertiaire | K20: S21 | L20: BTA1189363 | M20: 9841150 | N20: 1 | O20: 50002534214233 | P20: 284.375 | Q20: 250 | R20: 239 | S20: 1281 | T20: 364284.38 | U20: 0.054 | V20: 0.879 | W20: 1305.3 | X20: BT | Y20: 45300 | Z20: 0.1208 | AA20: FALSE | AB20: FALSE | AC20: EDF OA | AD20: ENEDIS | AE20: 1248.818 | AF20: 45.02889 | AG20: 3.06218 | AH20: N°3 - Fuji (SPV 11&15) | AI20: RAS | AJ20: EIFFAGE | AK20: Patrice GUENIOT | AL20: p.gueniot@gmail.com | AN20: +33682515030 | AO20: +33630237363 | AP20: 3C INSTAL | AQ20: MOMSTEEL | AR20: FALSE | AV20: FALSE | AZ20: FALSE | BD20: Yasser BADREZZAMANE | BE20: Jean-Paul THOROGOOD | BF20: Martin DE GUERRE | BG20: Alexandre COL | BH20: Contrat OM PV toiture - ENERLIS - V10 18.11.2020 exécuté | BI20: DEV-CONT-SPV015_Contrat_DEV_EPC_DAVAI_ENR-1 (signed) (1) | BJ20: EX-CONT-SPV015-Contrat_Suivi_OM_Gestion_Actifs_DAVAI -ENR-01 | BK20: 856 | BL20: 175.76562 | BX20: Siège de l’entreprise, stockage de matériaux de TP, de matériaux et de véhicules | CB20: FALSE | CC20: Élément | CD20: sites/ServiceOM-AssetManagement/Lists/Exploitation Data Centrale
A21: 98047 | B21: TURROU | C21: DAVAI ENRSPV13 | D21: 45931 | E21: Les Campespieux | F21: 65380 | G21: Bénac | H21: BaC | I21: Toiture inclinée | J21: Agriculteur | K21: S21 | L21: BTA1202102 | BTA1202304 | M21: 9647750 | 9648250 | N21: 2 | O21: 50058684362448 | 50009769744265 | P21: 494.4 | Q21: 440 | R21: 416 | S21: 1172 | T21: 579436.8 | U21: 0.054 | V21: 0.87389713 | W21: 1152.1331 | X21: BT | Y21: 45314 | Z21: 0.1208 | AA21: FALSE | AB21: FALSE | AC21: EDF OA | AD21: ENEDIS | AE21: 2157.956 | AF21: 43.15845 | AG21: 0.02822 | AH21: N°3 - Kyoto (SPV 10,13 &14) | AI21: Mot de passe onduleur : Exploitation2023 | AJ21: EIFFAGE | AK21: Lorraine TURROU | AL21: etrierdebigorre@outlook.fr | AN21: +33485880404 | AO21: +33665671903 | AP21: ACROM | AQ21: HBBAT | AR21: FALSE | AV21: FALSE | AZ21: FALSE | BD21: Yasser BADREZZAMANE | BE21: Johan LAGARDE | BF21: Gwendal HART | BG21: Victor REVUELTA | BH21: MTN-CONT-004-Contrat_EIFFAGE_maintenance_PV_BT-001 | BI21: DEV-CONT-SPV013-Contrat_DEV_EPC_DAVAI_ENR-1 | BJ21: EX-CONT-SPV013-Contrat_Suivi_OM_Gestion_Actifs_DAVAI -ENR-01 | BK21: 856 | BL21: 252.8448 | BX21: Manège équestre, Stockage matériel + fourrage | CB21: FALSE | CC21: Élément | CD21: sites/ServiceOM-AssetManagement/Lists/Exploitation Data Centrale
A22: 99135 | B22: DELLA LIBERA CARBONNIERES | C22: DAVAI ENRSPV14 | D22: 45924 | E22: Carbonnières | F22: 47800 | G22: Lavergne | H22: BE | I22: Toiture plate | J22: Agriculteur | K22: S21 | L22: BTA1136662 | M22: 9550800 | N22: 1 | O22: 50001522816933 | P22: 296.205 | Q22: 250 | R22: 239 | S22: 1257 | T22: 372329.68 | U22: 0.054 | V22: 0.868 | W22: 1247.4 | X22: BT | Y22: 45209 | Z22: 0.1238 | AA22: FALSE | AB22: FALSE | AC22: EDF OA | AD22: ENEDIS | AE22: 1300.768 | AF22: 44.58495 | AG22: 0.41326 | AH22: N°3 - Kyoto (SPV 10,13 &14) | AI22: Mot de passe onduleur : Exploitation2023 | AJ22: EIFFAGE | AK22: Mickael DELLA LIBERA | AL22: della-libera.mickael@orange.fr | AN22: +33679213316 | AP22: HBBAT | AQ22: HBBAT | AR22: FALSE | AV22: FALSE | AZ22: FALSE | BD22: Yasser BADREZZAMANE | BE22: Victor PONTAIS | BF22: Gwendal HART | BG22: Victor REVUELTA | BH22: MTN-CONT-004-Contrat_EIFFAGE_maintenance_PV_BT-001 | BI22: DEV-CONT-SPV014_Contrat_DEV_EPC_DAVAI_ENR-1 (signed) (1) | BJ22: EX-CONT-SPV014-Contrat_Suivi_OM_Gestion_Actifs_DAVAI -ENR-01 (1) | BK22: 856 | BL22: 180.10724 | BX22: Stockage matériel, fourrage et stabulation | CB22: FALSE | CC22: Élément | CD22: sites/ServiceOM-AssetManagement/Lists/Exploitation Data Centrale
